Workbook

Sheet Synthèse
A1: CHIFFRAGE COR PHASE 2 — Data Products Direct Debits Cash Flow
A2: v5 — Recalcul « Annule & Remplace » sur 6 mois depuis la photo DCP mensuelle | 7 pays × 2 data products | flux unique | sans backfill 48 mois
A4: Lot | B4: Description | C4: Profil | D4: Charge (j) | E4: % Total
A5: LOT 0 | B5: Cadrage & essai technique (POC) | C5: Data Engineer | D5: ='Détail charges'!E9 -> 4 | E5: =IF(D20=0,0,D5/D20) -> 0.076190476
A6: LOT 1 | B6: COR_dataset — Lecture des photos DCP | C6: Data Engineer | D6: ='Détail charges'!E18 -> 5.5 | E6: =IF(D20=0,0,D6/D20) -> 0.1047619
A7: LOT 2 | B7: COR_design — Stage 1 (jointures & règles 1-3) | C7: Data Engineer | D7: ='Détail charges'!E27 -> 5.5 | E7: =IF(D20=0,0,D7/D20) -> 0.1047619
A8: LOT 3 | B8: COR_design — Stage 2 (groupes, ordre, flags, fenêtre) | C8: Data Engineer | D8: ='Détail charges'!E36 -> 9 | E8: =IF(D20=0,0,D8/D20) -> 0.17142857
A9: LOT 4 | B9: COR_product — DETAILS | C9: Data Engineer | D9: ='Détail charges'!E45 -> 4 | E9: =IF(D20=0,0,D9/D20) -> 0.076190476
A10: LOT 5 | B10: COR_product — KPI & reprise phase 1 | C10: Data Engineer | D10: ='Détail charges'!E52 -> 6 | E10: =IF(D20=0,0,D10/D20) -> 0.11428571
A11: LOT 6 | B11: Orchestration & exploitation | C11: MLOps | D11: ='Détail charges'!E60 -> 5.5 | E11: =IF(D20=0,0,D11/D20) -> 0.1047619
A12: LOT 7 | B12: Démarrage (initialisation) | C12: Data Engineer | D12: ='Détail charges'!E65 -> 1.5 | E12: =IF(D20=0,0,D12/D20) -> 0.028571429
A13: LOT 8 | B13: Recette fonctionnelle (UAT) | C13: Data Engineer | D13: ='Détail charges'!E71 -> 5.5 | E13: =IF(D20=0,0,D13/D20) -> 0.1047619
A14: LOT 9 | B14: Documentation technique | C14: Data Engineer | D14: ='Détail charges'!E76 -> 1.5 | E14: =IF(D20=0,0,D14/D20) -> 0.028571429
A15: LOT 10 | B15: Gestion de projet & coordination | C15: Data Engineer | D15: ='Détail charges'!E80 -> 1.5 | E15: =IF(D20=0,0,D15/D20) -> 0.028571429
A16: LOT 11 | B16: Évolution specs & marge technique | C16: Data Engineer | D16: ='Détail charges'!E85 -> 3 | E16: =IF(D20=0,0,D16/D20) -> 0.057142857
B18: Sous-total Data Engineer | C18: Data Engineer | D18: =SUMIF($C$5:$C$16,C18,$D$5:$D$16) -> 47 | E18: =IF(D20=0,0,D18/D20) -> 0.8952381
B19: Sous-total MLOps | C19: MLOps | D19: =SUMIF($C$5:$C$16,C19,$D$5:$D$16) -> 5.5 | E19: =IF(D20=0,0,D19/D20) -> 0.1047619
A20: ▶ | B20: TOTAL GÉNÉRAL | C20: DE + MLOps | D20: =SUM(D5:D16) -> 52.5 | E20: =IF(D20=0,0,D20/D20) -> 1
B22: Jours ouvrés par mois (hypothèse) | D22: 21
B23: Plafond demandé (mois) | D23: 2.5
B24: Charge totale en mois | D24: =IF(D22=0,0,D20/D22) -> 2.5
B25: Charge Data Engineer en mois (chemin critique) | D25: =IF(D22=0,0,D18/D22) -> 2.2380952
B26: Durée calendaire planifiée (semaines) | D26: =MAX(Planning!F:F) -> 11
B27: Respect du plafond (charge totale ≤ plafond) | D27: =IF(D24<=D23,"OK","DÉPASSEMENT") -> OK
A29: Hypothèses principales :
A30: • Mécanisme : chaque mois, la photo DCP M recalcule et remplace les mois d'émission M-5 → M (note d'historisation : « Annule & Remplace » 5 mois + insert du nouveau mois). Mois plus anciens figés.
A31: • Pas de backfill 48 mois : la plus ancienne photo DCP est juillet 2026 (→ février 2026). L'historique antérieur vient d'une reprise unique des KPI de la phase 1 (PostgreSQL, ≥ 4 ans).
A32: • Flux unique pour les 7 pays (tables DCP contiennent le pays) au lieu de 7 recettes par étape comme en phase 1 — à valider (impact si ×7 : voir onglet Hypothèses & risques).
A33: • Règles 4-6 en option B (photo 15 mois + mois figés de DETAILS) ; option A (photo seule) = environ -1 j.
A34: • Standards phase 1 réutilisés : 3 projets DATASET / DESIGN / PRODUCT, lib + recettes courtes, Great Expectations, pytest, scénarios chaînés.
A35: • Hors périmètre : déploiement et environnements (dev → test → prod).
A36: • Profil : développeur senior Dataiku / PySpark confirmé + MLOps à temps partiel.

Sheet Détail charges
A1: DÉTAIL DES CHARGES — COR PHASE 2 (v5)
A3: Lot | B3: ID | C3: Activité | D3: Profil | E3: Charge (j) | F3: Commentaire / Justification | G3: Dépend de | H3: Critère de fin (DoD)
A4: LOT 0 | B4: Cadrage & essai technique (POC) | E4: =E9 -> 4
B5: T0.1 | C5: Accès COS DCP + lecture d'une photo réelle (7 tables × 7 pays) | D5: Data Engineer | E5: 1 | F5: Vérifier sur données réelles : profondeur 15 mois (prélèvements) / 6 mois (échecs), colonnes vs mapping, nommage fichiers (préfixe + timestamp de dépôt), mode de découpage de la fenêtre par DCP. | G5: — | H5: Rapport de vérification partagé ; écarts vs mapping listés
B6: T0.2 | C6: POC PySpark : lecture CSV d'une photo (~25 M lignes) + filtres | D6: Data Engineer | E6: 1 | F6: Mesurer la durée réelle d'un run (base du nombre de cycles de test). Spark sur Kubernetes, comme les recettes PySpark existantes. | G6: T0.1 | H6: Durée de lecture + filtres mesurée et documentée
B7: T0.3 | C7: POC PostgreSQL : écriture ~6 mois de DETAILS + publication en transaction | D7: Data Engineer | E7: 1 | F7: Mesurer la vitesse d'écriture et valider le principe 'table de préparation → suppression fenêtre + insertion' en une transaction. | G7: T0.2 | H7: Temps d'écriture mesuré ; publication transactionnelle validée
B8: T0.4 | C8: Atelier métier : levée des points ouverts | D8: Data Engineer | E8: 1 | F8: Option A/B (recherche des tentatives précédentes), clé de groupe (règle 4 vs 5), délai max d'échec (docs : ~3 mois / métier : 5 mois), tentatives > 3, définition du mois des KPI, anomalies mapping (règles 6, 9-12, formule taux de succès). | G8: — | H8: Décisions tracées et validées par le métier
B9: Sous-total LOT 0 | E9: =SUM(E5:E8) -> 4
A11: LOT 1 | B11: COR_dataset — Lecture des photos DCP | E11: =E18 -> 5.5
B12: T1.1 | C12: Paramétrage des datasets DCP existants (7 tables) par mois d'arrêté | D12: Data Engineer | E12: 1 | F12: Réutilisation des datasets du data engineer (pointent déjà sur DCP, colonnes définies). Ajout : variable 'mois photo', sélection du fichier par préfixe suivi de chiffres (éviter c_cash_flow_ vs c_cash_flow_ctr_…). | G12: T0.1 | H12: Lecture d'une photo donnée par simple changement de variable
B13: T1.2 | C13: Recette de contrôle de complétude de la photo | D13: Data Engineer | E13: 1 | F13: 7 tables × 7 pays présentes et non vides ; lecture de la date de dépôt (timestamp du nom de fichier) pour détecter un redépôt. Arrêt + alerte si incomplet, rien n'est écrit. | G13: T1.1 | H13: Run bloqué si une table/pays manque ; testé sur un cas incomplet
B14: T1.3 | C14: Lib filters.py (PySpark) : filtres, sélection de colonnes, typage | D14: Data Engineer | E14: 1.5 | F14: TECH_UPDATE_TYPE_TRUSTED <> 'L', COD_PAYMENT_METHOD = 'DIRECT_DEBIT', COD_CASH_FLOW_DIRECTION = 'CREDIT', ID_LEASING_INVOICE commence par 'FLL'. Lib métier réécrite (schéma différent de la phase 1). | G14: T1.1 | H14: Fonctions de la lib couvertes par tests unitaires
B15: T1.4 | C15: Contrats Great Expectations sur les sorties dataset | D15: Data Engineer | E15: 0.5 | F15: Réutilisation de expectation_runner / dataiku_extender de la phase 1 (standard projet). | G15: T1.3 | H15: Contrats générés et passants sur la photo réelle
B16: T1.5 | C16: Tests unitaires pytest (lib dataset) | D16: Data Engineer | E16: 0.5 | F16: Même standard que test_prepare_dataset.py de la phase 1. | G16: T1.3 | H16: Tests verts
B17: T1.6 | C17: Scénario BUILD_DATASET + cycles de test sur photo réelle | D17: Data Engineer | E17: 1 | F17: Reprise de la structure des scénarios phase 1 (variables, GX_FILES, LOGS). | G17: T1.2, T1.4 | H17: Scénario exécuté de bout en bout sur une photo réelle
B18: Sous-total LOT 1 | E18: =SUM(E12:E17) -> 5.5
A20: LOT 2 | B20: COR_design — Stage 1 (jointures & règles 1-3) | E20: =E27 -> 5.5
B21: T2.1 | C21: Lib joins.py : jointures des 7 tables | D21: Data Engineer | E21: 1.5 | F21: Clés toujours pays + métier + id. CTR_FIN_CDT_INVOICE ↔ CASH_FLOW (inner) ↔ DIRECT_DEBIT_CASH_FLOW, LEASING_FINANCING_CONDITION, DTM_T_MARCHE_IBL_CTR (left). | G21: T1.6 | H21: Volumétrie après jointure contrôlée (pas de duplication)
B22: T2.2 | C22: Règles 1-3 : motif, libellé et date d'échec | D22: Data Engineer | E22: 1 | F22: FAILED_CASH_FLOW + TYP_CASH_FLOW_FAILURE_REASON. Pas de mise à jour ligne à ligne : recalcul de la fenêtre. | G22: T2.1 | H22: Règles 1-3 conformes au mapping sur jeu de test
B23: T2.3 | C23: Périodicité / marché / IBL : dernière valeur connue | D23: Data Engineer | E23: 0.5 | F23: Décision validée (option A) : dernière valeur pendant la vie de la ligne, figée ensuite. | G23: T2.1 | H23: Valeurs présentes sur toutes les lignes de la fenêtre
B24: T2.4 | C24: Recette PySpark Stage 1 (flux unique 7 pays) | D24: Data Engineer | E24: 0.5 | F24: Un seul flux partitionné par pays au lieu de 7 recettes (×7) comme en phase 1. | G24: T2.2, T2.3 | H24: Recette exécutée sur la photo réelle
B25: T2.5 | C25: Tests unitaires + contrats GX Stage 1 | D25: Data Engineer | E25: 1 | F25: Standard phase 1. | G25: T2.4 | H25: Tests verts ; contrats passants
B26: T2.6 | C26: [CYCLES TEST] Stage 1 | D26: Data Engineer | E26: 1 | F26: ~4 runs (voir onglet Analyse cycles test). Durée par run à confirmer au POC (T0.2). | G26: T2.4 | H26: Sortie Stage 1 stable
B27: Sous-total LOT 2 | E27: =SUM(E21:E26) -> 5.5
A29: LOT 3 | B29: COR_design — Stage 2 (groupes, ordre, flags, fenêtre) | E29: =E36 -> 9
B30: T3.1 | C30: Lib business_rules.py — règles 4-6 (groupe, ordre, date du DD initial) | D30: Data Engineer | E30: 3 | F30: Option B : tentatives précédentes cherchées dans les 15 mois de la photo ET dans les mois figés de DETAILS (conforme aux règles 4-6 du mapping). Calcul en une passe (tri par facture + date) au lieu du multi-pass ligne à ligne. | G30: T2.6 | H30: Groupes/ordres conformes aux exemples des slides 15-17 (session 1)
B31: T3.2 | C31: Règles 7-12 : les 6 flags | D31: Data Engineer | E31: 1 | F31: Ordre 1 / 2 / 3 × émis / en échec. Ordre > 3 non flagué (validé métier). | G31: T3.1 | H31: Flags conformes sur jeu de test
B32: T3.3 | C32: Fenêtre de recalcul M-5 → M + colonnes de traçabilité | D32: Data Engineer | E32: 0.5 | F32: Ne garder que les lignes émises entre M-5 et M ; colonnes mois de la photo + date du run. | G32: T3.2 | H32: Seuls les 6 mois de la fenêtre sont produits
B33: T3.4 | C33: Tests unitaires — jeux séquentiels | D33: Data Engineer | E33: 2 | F33: Cas : groupe sur plusieurs mois, frontière de fenêtre, échec tardif (5 mois), suppression logique ('L'), redépôt, facture déjà connue dans les mois figés. | G33: T3.1 | H33: Tous les cas listés testés et verts
B34: T3.5 | C34: [CYCLES TEST] Stage 2 | D34: Data Engineer | E34: 2 | F34: ~5 runs : règles 4-6 = bugs subtils visibles uniquement en run complet. | G34: T3.3 | H34: Sortie Stage 2 stable
B35: T3.6 | C35: Scénario BUILD_DESIGN + test bout en bout design | D35: Data Engineer | E35: 0.5 | F35: Enchaînement Stage 1 → Stage 2. | G35: T3.5 | H35: Scénario exécuté sans erreur
B36: Sous-total LOT 3 | E36: =SUM(E30:E35) -> 9
A38: LOT 4 | B38: COR_product — DETAILS | E38: =E45 -> 4
B39: T4.1 | C39: Tables PostgreSQL DETAILS + DETAILS_TMP + index | D39: Data Engineer | E39: 0.5 | F39: Index pays + mois d'émission. | G39: T0.3 | H39: Tables créées ; index en place
B40: T4.2 | C40: Recette d'écriture DETAILS_TMP (fenêtre de 6 mois) | D40: Data Engineer | E40: 0.5 | F40: Table de préparation non visible par Power BI. | G40: T3.6, T4.1 | H40: DETAILS_TMP alimentée
B41: T4.3 | C41: Contrôles qualité avant publication | D41: Data Engineer | E41: 1 | F41: Doublons sur la clé, colonnes obligatoires, volumes par pays/mois vs run précédent (seuil). Échec = arrêt, rien publié. | G41: T4.2 | H41: Contrôles bloquants testés (cas OK et KO)
B42: T4.4 | C42: Publication en transaction (Execute SQL) | D42: Data Engineer | E42: 1 | F42: Suppression des mois M-5 → M de DETAILS + insertion depuis DETAILS_TMP, tout ou rien. | G42: T4.3 | H42: Relance = même résultat (idempotence vérifiée)
B43: T4.5 | C43: Purge > 4 ans | D43: Data Engineer | E43: 0.5 | F43: Conservation 4 ans glissants (note d'historisation). | G43: T4.4 | H43: Purge testée
B44: T4.6 | C44: Tests + [CYCLES TEST] DETAILS | D44: Data Engineer | E44: 0.5 | G44: T4.4 | H44: DETAILS validée sur photo réelle
B45: Sous-total LOT 4 | E45: =SUM(E39:E44) -> 4
...

Sheet Planning
A1: PLANNING — COR PHASE 2 (v5) — semaines S1 à S11 (≈ 2,5 mois)
B2: Date de démarrage (lundi) : | C2: 46307
G3: 1 | H3: 2 | I3: 3 | J3: 4 | K3: 5 | L3: 6 | M3: 7 | N3: 8 | O3: 9 | P3: 10 | Q3: 11
A4: ID | B4: Lot / Tâche | C4: Profil | D4: Charge (j) | E4: Sem. début | F4: Sem. fin | G4: S1 | H4: S2 | I4: S3 | J4: S4 | K4: S5 | L4: S6 | M4: S7 | N4: S8 | O4: S9 | P4: S10 | Q4: S11
B5: Début de semaine → | G5: =$C$2+7*0 -> 46307 | H5: =$C$2+7*1 -> 46314 | I5: =$C$2+7*2 -> 46321 | J5: =$C$2+7*3 -> 46328 | K5: =$C$2+7*4 -> 46335 | L5: =$C$2+7*5 -> 46342 | M5: =$C$2+7*6 -> 46349 | N5: =$C$2+7*7 -> 46356 | O5: =$C$2+7*8 -> 46363 | P5: =$C$2+7*9 -> 46370 | Q5: =$C$2+7*10 -> 46377
A6: LOT 0 | B6: Cadrage & essai technique (POC) | D6: ='Détail charges'!E9 -> 4 | E6: =MIN(E7:E10) -> 1 | F6: =MAX(F7:F10) -> 1
A7: T0.1 | B7: Accès COS DCP + lecture d'une photo réelle (7 tables × 7 pays) | C7: Data Engineer | D7: ='Détail charges'!E5 -> 1 | E7: 1 | F7: 1
A8: T0.2 | B8: POC PySpark : lecture CSV d'une photo (~25 M lignes) + filtres | C8: Data Engineer | D8: ='Détail charges'!E6 -> 1 | E8: 1 | F8: 1
A9: T0.3 | B9: POC PostgreSQL : écriture ~6 mois de DETAILS + publication en transaction | C9: Data Engineer | D9: ='Détail charges'!E7 -> 1 | E9: 1 | F9: 1
A10: T0.4 | B10: Atelier métier : levée des points ouverts | C10: Data Engineer | D10: ='Détail charges'!E8 -> 1 | E10: 1 | F10: 1
A11: LOT 1 | B11: COR_dataset — Lecture des photos DCP | D11: ='Détail charges'!E18 -> 5.5 | E11: =MIN(E12:E17) -> 2 | F11: =MAX(F12:F17) -> 3
A12: T1.1 | B12: Paramétrage des datasets DCP existants (7 tables) par mois d'arrêté | C12: Data Engineer | D12: ='Détail charges'!E12 -> 1 | E12: 2 | F12: 2
A13: T1.2 | B13: Recette de contrôle de complétude de la photo | C13: Data Engineer | D13: ='Détail charges'!E13 -> 1 | E13: 2 | F13: 2
A14: T1.3 | B14: Lib filters.py (PySpark) : filtres, sélection de colonnes, typage | C14: Data Engineer | D14: ='Détail charges'!E14 -> 1.5 | E14: 2 | F14: 2
A15: T1.4 | B15: Contrats Great Expectations sur les sorties dataset | C15: Data Engineer | D15: ='Détail charges'!E15 -> 0.5 | E15: 2 | F15: 3
A16: T1.5 | B16: Tests unitaires pytest (lib dataset) | C16: Data Engineer | D16: ='Détail charges'!E16 -> 0.5 | E16: 3 | F16: 3
A17: T1.6 | B17: Scénario BUILD_DATASET + cycles de test sur photo réelle | C17: Data Engineer | D17: ='Détail charges'!E17 -> 1 | E17: 3 | F17: 3
A18: LOT 2 | B18: COR_design — Stage 1 (jointures & règles 1-3) | D18: ='Détail charges'!E27 -> 5.5 | E18: =MIN(E19:E24) -> 3 | F18: =MAX(F19:F24) -> 4
A19: T2.1 | B19: Lib joins.py : jointures des 7 tables | C19: Data Engineer | D19: ='Détail charges'!E21 -> 1.5 | E19: 3 | F19: 3
A20: T2.2 | B20: Règles 1-3 : motif, libellé et date d'échec | C20: Data Engineer | D20: ='Détail charges'!E22 -> 1 | E20: 3 | F20: 4
A21: T2.3 | B21: Périodicité / marché / IBL : dernière valeur connue | C21: Data Engineer | D21: ='Détail charges'!E23 -> 0.5 | E21: 4 | F21: 4
A22: T2.4 | B22: Recette PySpark Stage 1 (flux unique 7 pays) | C22: Data Engineer | D22: ='Détail charges'!E24 -> 0.5 | E22: 4 | F22: 4
A23: T2.5 | B23: Tests unitaires + contrats GX Stage 1 | C23: Data Engineer | D23: ='Détail charges'!E25 -> 1 | E23: 4 | F23: 4
A24: T2.6 | B24: [CYCLES TEST] Stage 1 | C24: Data Engineer | D24: ='Détail charges'!E26 -> 1 | E24: 4 | F24: 4
A25: LOT 3 | B25: COR_design — Stage 2 (groupes, ordre, flags, fenêtre) | D25: ='Détail charges'!E36 -> 9 | E25: =MIN(E26:E31) -> 4 | F25: =MAX(F26:F31) -> 6
A26: T3.1 | B26: Lib business_rules.py — règles 4-6 (groupe, ordre, date du DD initial) | C26: Data Engineer | D26: ='Détail charges'!E30 -> 3 | E26: 4 | F26: 5
A27: T3.2 | B27: Règles 7-12 : les 6 flags | C27: Data Engineer | D27: ='Détail charges'!E31 -> 1 | E27: 5 | F27: 5
A28: T3.3 | B28: Fenêtre de recalcul M-5 → M + colonnes de traçabilité | C28: Data Engineer | D28: ='Détail charges'!E32 -> 0.5 | E28: 5 | F28: 5
A29: T3.4 | B29: Tests unitaires — jeux séquentiels | C29: Data Engineer | D29: ='Détail charges'!E33 -> 2 | E29: 5 | F29: 6
A30: T3.5 | B30: [CYCLES TEST] Stage 2 | C30: Data Engineer | D30: ='Détail charges'!E34 -> 2 | E30: 6 | F30: 6
A31: T3.6 | B31: Scénario BUILD_DESIGN + test bout en bout design | C31: Data Engineer | D31: ='Détail charges'!E35 -> 0.5 | E31: 6 | F31: 6
A32: LOT 4 | B32: COR_product — DETAILS | D32: ='Détail charges'!E45 -> 4 | E32: =MIN(E33:E38) -> 6 | F32: =MAX(F33:F38) -> 7
A33: T4.1 | B33: Tables PostgreSQL DETAILS + DETAILS_TMP + index | C33: Data Engineer | D33: ='Détail charges'!E39 -> 0.5 | E33: 6 | F33: 6
A34: T4.2 | B34: Recette d'écriture DETAILS_TMP (fenêtre de 6 mois) | C34: Data Engineer | D34: ='Détail charges'!E40 -> 0.5 | E34: 6 | F34: 6
A35: T4.3 | B35: Contrôles qualité avant publication | C35: Data Engineer | D35: ='Détail charges'!E41 -> 1 | E35: 7 | F35: 7
A36: T4.4 | B36: Publication en transaction (Execute SQL) | C36: Data Engineer | D36: ='Détail charges'!E42 -> 1 | E36: 7 | F36: 7
A37: T4.5 | B37: Purge > 4 ans | C37: Data Engineer | D37: ='Détail charges'!E43 -> 0.5 | E37: 7 | F37: 7
A38: T4.6 | B38: Tests + [CYCLES TEST] DETAILS | C38: Data Engineer | D38: ='Détail charges'!E44 -> 0.5 | E38: 7 | F38: 7
A39: LOT 5 | B39: COR_product — KPI & reprise phase 1 | D39: ='Détail charges'!E52 -> 6 | E39: =MIN(E40:E43) -> 7 | F39: =MAX(F40:F43) -> 8
A40: T5.1 | B40: KPI en SQL : 7 axes, compteurs, montants, taux — fenêtre 6 mois | C40: Data Engineer | D40: ='Détail charges'!E48 -> 2 | E40: 7 | F40: 7
...

Sheet Écarts vs v4
A1: ÉCARTS ENTRE LE CHIFFRAGE v4 (Option C) ET LE CHIFFRAGE v5
A3: Thème | B3: v4 (j) | C3: v5 (j) | D3: Écart (j) | E3: Raison du changement
A4: Cadrage & essai technique (POC) | B4: 0 | C4: ='Détail charges'!E9 -> 4 | D4: =C4-B4 -> 4 | E4: Nouveau lot : vérifier une vraie photo DCP et mesurer Spark / PostgreSQL avant de développer (en v4, l'analyse specs était répartie dans les lots 1, 2 et 10).
A5: COR_dataset | B5: 9 | C5: ='Détail charges'!E18 -> 5.5 | D5: =C5-B5 -> -3.5 | E5: Datasets du data engineer réutilisés (pointent déjà sur DCP, colonnes définies). Un seul flux pour 7 pays au lieu de 7 recettes.
A6: COR_design — jointures & règles 1-3 (v4 : lots 2 + 3) | B6: 14 | C6: ='Détail charges'!E27 -> 5.5 | D6: =C6-B6 -> -8.5 | E6: Flux unique au lieu de ×7 ; moins de cycles de test (1 photo par run).
A7: COR_design — règles 4-12 (v4 : lot 4) | B7: 13 | C7: ='Détail charges'!E36 -> 9 | D7: =C7-B7 -> -4 | E7: Calcul en une passe (tri par facture) au lieu du multi-pass ligne à ligne ; fenêtre de 6 mois ajoutée ; flux unique.
A8: COR_product — DETAILS (v4 : lot 5) | B8: 4.5 | C8: ='Détail charges'!E45 -> 4 | D8: =C8-B8 -> -0.5 | E8: Ajout des contrôles avant publication et de la publication en transaction ; flux unique.
A9: COR_product — KPI & historisation (v4 : lot 6) | B9: 14 | C9: ='Détail charges'!E52 -> 6 | D9: =C9-B9 -> -8 | E9: Suppression du backfill 48 mois × 7 pays (~1,85 Md lignes) : photos DCP disponibles seulement depuis juillet 2026 → reprise unique des KPI phase 1. Annule & Remplace 6 mois au lieu d'un mécanisme par mois avec checkpoints.
A10: MLOps & orchestration (v4 : lot 7) | B10: 9 | C10: ='Détail charges'!E60 -> 5.5 | D10: =C10-B10 -> -3.5 | E10: Déploiement multi-environnements hors périmètre. Ajout du journal des runs et du mode rejeu / reconstruction.
A11: Démarrage (initialisation) | B11: 0 | C11: ='Détail charges'!E65 -> 1.5 | D11: =C11-B11 -> 1.5 | E11: Nouveau : rejeu des photos juillet → septembre 2026 (remplace le backfill).
A12: Recette fonctionnelle (v4 : lot 8) | B12: 7 | C12: ='Détail charges'!E71 -> 5.5 | D12: =C12-B12 -> -1.5 | E12: Recette centrée sur la comparaison phase 1 / phase 2 sur les mois communs.
A13: Documentation (v4 : lot 9) | B13: 3 | C13: ='Détail charges'!E76 -> 1.5 | D13: =C13-B13 -> -1.5 | E13: Un seul flux à documenter au lieu de 7.
A14: Gestion de projet (v4 : lot 10) | B14: 4 | C14: ='Détail charges'!E80 -> 1.5 | D14: =C14-B14 -> -2.5 | E14: Analyse des specs et cadrage déjà réalisés (conception validée) ; reste le suivi.
A15: Évolution specs & marge (v4 : lot 11) | B15: 8 | C15: ='Détail charges'!E85 -> 3 | D15: =C15-B15 -> -5 | E15: Marge réduite pour tenir 2,5 mois : risque assumé, voir onglet Hypothèses & risques.
A16: TOTAL | B16: =SUM(B4:B15) -> 85.5 | C16: =SUM(C4:C15) -> 52.5 | D16: =SUM(D4:D15) -> -33 | E16: Source v4 : Chiffrage_COR_Phase2_OptionC_v4.xlsx (onglet Synthèse).

Sheet Analyse cycles test
A1: ANALYSE — Cycles de test pipeline (v5)
A3: Lot / Stage | B3: Nb runs estimés | C3: Durée moy/run | D3: Charge (j) | E3: Justification
A4: LOT 1 — DATASET (1 flux) | B4: ~3 runs | C4: à mesurer (T0.2) | D4: ='Détail charges'!E17 -> 1 | E4: Lecture + contrôle de complétude + filtres sur une photo réelle.
A5: LOT 2 — Stage 1 (1 flux) | B5: ~4 runs | C5: à mesurer (T0.2) | D5: ='Détail charges'!E26 -> 1 | E5: Jointures : erreurs de clés, nulls, types.
A6: LOT 3 — Stage 2 (1 flux) | B6: ~5 runs | C6: à mesurer (T0.2) | D6: ='Détail charges'!E34 -> 2 | E6: Règles 4-6 : bugs subtils visibles uniquement en run complet.
A7: LOT 4 — DETAILS | B7: ~2 runs | C7: à mesurer (T0.2) | D7: ='Détail charges'!E44 -> 0.5 | E7: Écriture + publication + contrôles.
A8: LOT 5 — KPI | B8: ~3 runs | C8: à mesurer (T0.2) | D8: ='Détail charges'!E51 -> 1.5 | E8: Validation des agrégations et de la continuité avec la phase 1.
A9: LOT 6 — Bout en bout | B9: ~2 runs | C9: à mesurer (T0.2) | D9: ='Détail charges'!E59 -> 1.5 | E9: Scénario mensuel complet + mesure de performance.
A11: TOTAL cycles de test | D11: =SUM(D4:D9) -> 7.5 | E11: =D11/'Détail charges'!E87 -> 0.14285714
A13: Note : en v4 un run durait 2 à 5 h (pipeline phase 1, ×7 pays). En v5 un run traite une seule photo (~25 M lignes, 7 pays) en PySpark : la durée réelle sera mesurée au POC (T0.2). Pendant le développement, travailler sur un pays ou un échantillon réduit pour raccourcir les cycles.

Sheet Hypothèses & risques
A1: HYPOTHÈSES, POINTS À CONFIRMER ET RISQUES
A3: ID | B3: Hypothèse / risque | C3: Impact (j) | D3: Si l'hypothèse tombe | E3: Levée / mitigation
A4: H1 | B4: Un seul flux Dataiku pour les 7 pays (écart au standard phase 1 : 7 recettes par étape). | C4: +6 à +8 | D4: Retour à 7 recettes par étape : recettes, tests et cycles multipliés. | E4: Validation du chef de projet avant démarrage.
A5: H2 | B5: Règles 4-6 en option B (photo 15 mois + mois figés de DETAILS). | C5: -1 | D5: Option A (photo seule) si le métier garantit qu'aucun prélèvement n'arrive > 15 mois après le premier. | E5: Atelier métier T0.4.
A6: H3 | B6: Photos DCP conservées sans limite et jamais modifiées (hors redépôt). | C6: +5 à +8 | D6: Il faudrait une copie de l'historique dans DLP (couche intermédiaire). | E6: Engagement écrit de DCP.
A7: H4 | B7: La photo contient 15 mois de prélèvements et 6 mois d'échecs (slides 8-10, session 1). | C7: +2 à +4 | D7: Si moins de 11 mois de prélèvements : lecture obligatoire des mois figés de DETAILS pour toutes les tentatives. | E7: Vérification T0.1.
A8: H5 | B8: KPI phase 1 disponibles ≥ 4 ans en PostgreSQL ; une seule colonne diffère. | C8: +1 à +3 | D8: Mapping de reprise plus lourd. | E8: Analyse des 7 tables xx_var_stats en T5.2.
A9: H6 | B9: Déploiement et environnements hors périmètre. | C9: +2 à +3 | D9: Chiffrage v4 : 1 j de configuration multi-env + tests. | E9: Confirmé par le demandeur.
A10: H7 | B10: Durée d'un run compatible avec ~19 cycles de test (voir Analyse cycles test). | C10: +2 à +5 | D10: Run trop long → moins d'itérations par jour. | E10: Mesure au POC (T0.2) ; dev sur échantillon.
A11: H8 | B11: 21 jours ouvrés par mois ; 1 Data Engineer senior à temps plein + 1 MLOps à temps partiel. | C11: — | D11: Profil junior ou temps partiel → durée calendaire allongée. | E11: Affectation confirmée avant démarrage.
A12: R1 | B12: Marge réduite à 3 j (v4 : 8 j) pour tenir 2,5 mois. | C12: — | D12: Tout imprévu > 3 j dépasse le plafond. | E12: Leviers : documentation réduite, recette en parallèle des corrections, MLOps en avance.
A13: R2 | B13: Anomalies du mapping (règle 6 sur le mauvais champ, renvois des règles 9-12, formule du taux de succès, versionnement). | C13: +1 à +2 | D13: Reprises de développement. | E13: Atelier métier T0.4.
A14: R3 | B14: Écarts phase 1 / phase 2 (nouvelle logique de comptage) difficiles à expliquer. | C14: +1 à +3 | D14: Recette prolongée. | E14: Préparer l'analyse des écarts dès T7.2.
A15: R4 | B15: Disponibilité du métier pendant la recette. | C15: — | D15: Glissement calendaire. | E15: Réserver les créneaux de recette dès le démarrage.
